{
 "cells": [
  {
   "cell_type": "code",
   "execution_count": 2,
   "metadata": {},
   "outputs": [],
   "source": [
    "from __future__ import print_function\n",
    "from __future__ import division\n",
    "\n",
    "import matplotlib.pyplot as plt\n",
    "import numpy as np\n",
    "import math\n",
    "\n",
    "from config import cfg\n",
    "from net import DCGAN\n",
    "import tensorflow as tf"
   ]
  },
  {
   "cell_type": "markdown",
   "metadata": {},
   "source": [
    "### Set parameters  \n",
    "All the parameters can be found in `config.py`"
   ]
  },
  {
   "cell_type": "code",
   "execution_count": 3,
   "metadata": {},
   "outputs": [],
   "source": [
    "cfg.beta1 = 0.\n",
    "cfg.beta2 = 0.99\n",
    "cfg.batch_size = 16\n",
    "cfg.save_period = 1000\n",
    "cfg.display_period = 100\n",
    "cfg.n_iters = 20000\n",
    "cfg.n_critic = 1\n",
    "cfg.learning_rate = 0.001\n",
    "cfg.norm_g = 'pixel_norm'\n",
    "cfg.norm_d = None\n",
    "cfg.weight_scale = True\n",
    "cfg.drift_loss = True\n",
    "cfg.loss_mode = 'wgan_gp'\n",
    "cfg.use_tanh = True\n",
    "cfg.save_images = True"
   ]
  },
  {
   "cell_type": "markdown",
   "metadata": {},
   "source": [
    "### Step-1 : Train at 8x8 resolution\n",
    "In the paper, they start with 4x4 resolution but it doesn't matter"
   ]
  },
  {
   "cell_type": "code",
   "execution_count": 4,
   "metadata": {},
   "outputs": [
    {
     "name": "stdout",
     "output_type": "stream",
     "text": [
      "Size of training set :  53080\n",
      "Size of validation set :  5898\n",
      "WARNING:tensorflow:From /home/aat414/deep_final_project/progressive_growing_of_GANs/net.py:29: calling reduce_mean (from tensorflow.python.ops.math_ops) with keep_dims is deprecated and will be removed in a future version.\n",
      "Instructions for updating:\n",
      "keep_dims is deprecated, use keepdims instead\n",
      "After 100 iterations Discriminator loss : 0.05087   Generator loss : -1.92685\n",
      "After 200 iterations Discriminator loss : -1.19733   Generator loss : 1.41205\n",
      "After 300 iterations Discriminator loss : -1.28041   Generator loss : 1.49783\n",
      "After 400 iterations Discriminator loss : -1.26788   Generator loss : 1.45132\n",
      "After 500 iterations Discriminator loss : -1.26336   Generator loss : 1.42576\n",
      "After 600 iterations Discriminator loss : -1.28301   Generator loss : 1.44535\n",
      "After 700 iterations Discriminator loss : -0.69052   Generator loss : 1.10882\n",
      "After 800 iterations Discriminator loss : -0.74943   Generator loss : 0.98583\n",
      "After 900 iterations Discriminator loss : -0.75852   Generator loss : 0.91767\n",
      "After 1000 iterations Discriminator loss : -0.75580   Generator loss : 0.86911\n",
      "Saving model in D:\\Data\\pgan\\models/8x8/model\n",
      "Loading model...\n",
      "INFO:tensorflow:Restoring parameters from D:\\Data\\pgan\\models/8x8/model-1000\n",
      "ERROR:tensorflow:Exception in QueueRunner: Enqueue operation was cancelled\n",
      "\t [[Node: input_producer/input_producer/input_producer_EnqueueMany = QueueEnqueueManyV2[Tcomponents=[DT_INT32], timeout_ms=-1, _device=\"/job:localhost/replica:0/task:0/device:CPU:0\"](input_producer/input_producer, input_producer/input_producer/RandomShuffle)]]\n",
      "ERROR:tensorflow:Exception in QueueRunner: Enqueue operation was cancelled\n",
      "\t [[Node: batch/fifo_queue_enqueue = QueueEnqueueV2[Tcomponents=[DT_FLOAT], timeout_ms=-1, _device=\"/job:localhost/replica:0/task:0/device:CPU:0\"](batch/fifo_queue, truediv_2)]]\n",
      "ERROR:tensorflow:Exception in QueueRunner: Enqueue operation was cancelled\n",
      "\t [[Node: batch/fifo_queue_enqueue = QueueEnqueueV2[Tcomponents=[DT_FLOAT], timeout_ms=-1, _device=\"/job:localhost/replica:0/task:0/device:CPU:0\"](batch/fifo_queue, truediv_2)]]\n",
      "ERROR:tensorflow:Exception in QueueRunner: Enqueue operation was cancelled\n",
      "\t [[Node: batch/fifo_queue_enqueue = QueueEnqueueV2[Tcomponents=[DT_FLOAT], timeout_ms=-1, _device=\"/job:localhost/replica:0/task:0/device:CPU:0\"](batch/fifo_queue, truediv_2)]]\n",
      "ERROR:tensorflow:Exception in QueueRunner: Enqueue operation was cancelled\n",
      "\t [[Node: batch/fifo_queue_enqueue = QueueEnqueueV2[Tcomponents=[DT_FLOAT], timeout_ms=-1, _device=\"/job:localhost/replica:0/task:0/device:CPU:0\"](batch/fifo_queue, truediv_2)]]\n",
      "ERROR:tensorflow:Exception in QueueRunner: Enqueue operation was cancelled\n",
      "\t [[Node: batch/fifo_queue_enqueue = QueueEnqueueV2[Tcomponents=[DT_FLOAT], timeout_ms=-1, _device=\"/job:localhost/replica:0/task:0/device:CPU:0\"](batch/fifo_queue, truediv_2)]]\n",
      "ERROR:tensorflow:Exception in QueueRunner: Enqueue operation was cancelled\n",
      "\t [[Node: batch/fifo_queue_enqueue = QueueEnqueueV2[Tcomponents=[DT_FLOAT], timeout_ms=-1, _device=\"/job:localhost/replica:0/task:0/device:CPU:0\"](batch/fifo_queue, truediv_2)]]\n",
      "ERROR:tensorflow:Exception in QueueRunner: Enqueue operation was cancelled\n",
      "\t [[Node: batch/fifo_queue_enqueue = QueueEnqueueV2[Tcomponents=[DT_FLOAT], timeout_ms=-1, _device=\"/job:localhost/replica:0/task:0/device:CPU:0\"](batch/fifo_queue, truediv_2)]]\n",
      "ERROR:tensorflow:Exception in QueueRunner: Enqueue operation was cancelled\n",
      "\t [[Node: batch/fifo_queue_enqueue = QueueEnqueueV2[Tcomponents=[DT_FLOAT], timeout_ms=-1, _device=\"/job:localhost/replica:0/task:0/device:CPU:0\"](batch/fifo_queue, truediv_2)]]\n",
      "ERROR:tensorflow:Exception in QueueRunner: Enqueue operation was cancelled\n",
      "\t [[Node: batch/fifo_queue_enqueue = QueueEnqueueV2[Tcomponents=[DT_FLOAT], timeout_ms=-1, _device=\"/job:localhost/replica:0/task:0/device:CPU:0\"](batch/fifo_queue, truediv_2)]]\n",
      "ERROR:tensorflow:Exception in QueueRunner: Enqueue operation was cancelled\n",
      "\t [[Node: batch/fifo_queue_enqueue = QueueEnqueueV2[Tcomponents=[DT_FLOAT], timeout_ms=-1, _device=\"/job:localhost/replica:0/task:0/device:CPU:0\"](batch/fifo_queue, truediv_2)]]\n",
      "ERROR:tensorflow:Exception in QueueRunner: Enqueue operation was cancelled\n",
      "\t [[Node: batch/fifo_queue_enqueue = QueueEnqueueV2[Tcomponents=[DT_FLOAT], timeout_ms=-1, _device=\"/job:localhost/replica:0/task:0/device:CPU:0\"](batch/fifo_queue, truediv_2)]]\n",
      "ERROR:tensorflow:Exception in QueueRunner: Enqueue operation was cancelled\n",
      "\t [[Node: batch/fifo_queue_enqueue = QueueEnqueueV2[Tcomponents=[DT_FLOAT], timeout_ms=-1, _device=\"/job:localhost/replica:0/task:0/device:CPU:0\"](batch/fifo_queue, truediv_2)]]\n",
      "ERROR:tensorflow:Exception in QueueRunner: Enqueue operation was cancelled\n",
      "\t [[Node: batch/fifo_queue_enqueue = QueueEnqueueV2[Tcomponents=[DT_FLOAT], timeout_ms=-1, _device=\"/job:localhost/replica:0/task:0/device:CPU:0\"](batch/fifo_queue, truediv_2)]]\n",
      "ERROR:tensorflow:Exception in QueueRunner: Enqueue operation was cancelled\n",
      "\t [[Node: batch/fifo_queue_enqueue = QueueEnqueueV2[Tcomponents=[DT_FLOAT], timeout_ms=-1, _device=\"/job:localhost/replica:0/task:0/device:CPU:0\"](batch/fifo_queue, truediv_2)]]\n",
      "ERROR:tensorflow:Exception in QueueRunner: Enqueue operation was cancelled\n",
      "\t [[Node: batch/fifo_queue_enqueue = QueueEnqueueV2[Tcomponents=[DT_FLOAT], timeout_ms=-1, _device=\"/job:localhost/replica:0/task:0/device:CPU:0\"](batch/fifo_queue, truediv_2)]]\n",
      "ERROR:tensorflow:Exception in QueueRunner: Enqueue operation was cancelled\n",
      "\t [[Node: batch/fifo_queue_enqueue = QueueEnqueueV2[Tcomponents=[DT_FLOAT], timeout_ms=-1, _device=\"/job:localhost/replica:0/task:0/device:CPU:0\"](batch/fifo_queue, truediv_2)]]\n"
     ]
    },
    {
     "name": "stderr",
     "output_type": "stream",
     "text": [
      "Exception in thread QueueRunnerThread-batch/fifo_queue-batch/fifo_queue_enqueue:\n",
      "Traceback (most recent call last):\n",
      "  File \"/share/apps/python3/3.6.3/intel/lib/python3.6/threading.py\", line 916, in _bootstrap_inner\n",
      "    self.run()\n",
      "  File \"/share/apps/python3/3.6.3/intel/lib/python3.6/threading.py\", line 864, in run\n",
      "    self._target(*self._args, **self._kwargs)\n",
      "  File \"/home/aat414/pyenv/py3.6.3/lib/python3.6/site-packages/tensorflow/python/training/queue_runner_impl.py\", line 252, in _run\n",
      "    enqueue_callable()\n",
      "  File \"/home/aat414/pyenv/py3.6.3/lib/python3.6/site-packages/tensorflow/python/client/session.py\", line 1259, in _single_operation_run\n",
      "    None)\n",
      "  File \"/home/aat414/pyenv/py3.6.3/lib/python3.6/site-packages/tensorflow/python/framework/errors_impl.py\", line 516, in __exit__\n",
      "    c_api.TF_GetCode(self.status.status))\n",
      "tensorflow.python.framework.errors_impl.CancelledError: Enqueue operation was cancelled\n",
      "\t [[Node: batch/fifo_queue_enqueue = QueueEnqueueV2[Tcomponents=[DT_FLOAT], timeout_ms=-1, _device=\"/job:localhost/replica:0/task:0/device:CPU:0\"](batch/fifo_queue, truediv_2)]]\n",
      "\n",
      "Exception in thread QueueRunnerThread-batch/fifo_queue-batch/fifo_queue_enqueue:\n",
      "Traceback (most recent call last):\n",
      "  File \"/share/apps/python3/3.6.3/intel/lib/python3.6/threading.py\", line 916, in _bootstrap_inner\n",
      "    self.run()\n",
      "  File \"/share/apps/python3/3.6.3/intel/lib/python3.6/threading.py\", line 864, in run\n",
      "    self._target(*self._args, **self._kwargs)\n",
      "  File \"/home/aat414/pyenv/py3.6.3/lib/python3.6/site-packages/tensorflow/python/training/queue_runner_impl.py\", line 252, in _run\n",
      "    enqueue_callable()\n",
      "  File \"/home/aat414/pyenv/py3.6.3/lib/python3.6/site-packages/tensorflow/python/client/session.py\", line 1259, in _single_operation_run\n",
      "    None)\n",
      "  File \"/home/aat414/pyenv/py3.6.3/lib/python3.6/site-packages/tensorflow/python/framework/errors_impl.py\", line 516, in __exit__\n",
      "    c_api.TF_GetCode(self.status.status))\n",
      "tensorflow.python.framework.errors_impl.CancelledError: Enqueue operation was cancelled\n",
      "\t [[Node: batch/fifo_queue_enqueue = QueueEnqueueV2[Tcomponents=[DT_FLOAT], timeout_ms=-1, _device=\"/job:localhost/replica:0/task:0/device:CPU:0\"](batch/fifo_queue, truediv_2)]]\n",
      "\n",
      "Exception in thread QueueRunnerThread-batch/fifo_queue-batch/fifo_queue_enqueue:\n",
      "Traceback (most recent call last):\n",
      "  File \"/share/apps/python3/3.6.3/intel/lib/python3.6/threading.py\", line 916, in _bootstrap_inner\n",
      "    self.run()\n",
      "  File \"/share/apps/python3/3.6.3/intel/lib/python3.6/threading.py\", line 864, in run\n",
      "    self._target(*self._args, **self._kwargs)\n",
      "  File \"/home/aat414/pyenv/py3.6.3/lib/python3.6/site-packages/tensorflow/python/training/queue_runner_impl.py\", line 252, in _run\n",
      "    enqueue_callable()\n",
      "  File \"/home/aat414/pyenv/py3.6.3/lib/python3.6/site-packages/tensorflow/python/client/session.py\", line 1259, in _single_operation_run\n",
      "    None)\n",
      "  File \"/home/aat414/pyenv/py3.6.3/lib/python3.6/site-packages/tensorflow/python/framework/errors_impl.py\", line 516, in __exit__\n",
      "    c_api.TF_GetCode(self.status.status))\n",
      "tensorflow.python.framework.errors_impl.CancelledError: Enqueue operation was cancelled\n",
      "\t [[Node: batch/fifo_queue_enqueue = QueueEnqueueV2[Tcomponents=[DT_FLOAT], timeout_ms=-1, _device=\"/job:localhost/replica:0/task:0/device:CPU:0\"](batch/fifo_queue, truediv_2)]]\n",
      "\n",
      "Exception in thread QueueRunnerThread-batch/fifo_queue-batch/fifo_queue_enqueue:\n",
      "Traceback (most recent call last):\n",
      "  File \"/share/apps/python3/3.6.3/intel/lib/python3.6/threading.py\", line 916, in _bootstrap_inner\n",
      "    self.run()\n",
      "  File \"/share/apps/python3/3.6.3/intel/lib/python3.6/threading.py\", line 864, in run\n",
      "    self._target(*self._args, **self._kwargs)\n",
      "  File \"/home/aat414/pyenv/py3.6.3/lib/python3.6/site-packages/tensorflow/python/training/queue_runner_impl.py\", line 252, in _run\n",
      "    enqueue_callable()\n",
      "  File \"/home/aat414/pyenv/py3.6.3/lib/python3.6/site-packages/tensorflow/python/client/session.py\", line 1259, in _single_operation_run\n",
      "    None)\n",
      "  File \"/home/aat414/pyenv/py3.6.3/lib/python3.6/site-packages/tensorflow/python/framework/errors_impl.py\", line 516, in __exit__\n",
      "    c_api.TF_GetCode(self.status.status))\n",
      "tensorflow.python.framework.errors_impl.CancelledError: Enqueue operation was cancelled\n",
      "\t [[Node: batch/fifo_queue_enqueue = QueueEnqueueV2[Tcomponents=[DT_FLOAT], timeout_ms=-1, _device=\"/job:localhost/replica:0/task:0/device:CPU:0\"](batch/fifo_queue, truediv_2)]]\n",
      "\n",
      "Exception in thread QueueRunnerThread-batch/fifo_queue-batch/fifo_queue_enqueue:\n",
      "Traceback (most recent call last):\n",
      "  File \"/share/apps/python3/3.6.3/intel/lib/python3.6/threading.py\", line 916, in _bootstrap_inner\n",
      "    self.run()\n",
      "  File \"/share/apps/python3/3.6.3/intel/lib/python3.6/threading.py\", line 864, in run\n",
      "    self._target(*self._args, **self._kwargs)\n",
      "  File \"/home/aat414/pyenv/py3.6.3/lib/python3.6/site-packages/tensorflow/python/training/queue_runner_impl.py\", line 252, in _run\n",
      "    enqueue_callable()\n",
      "  File \"/home/aat414/pyenv/py3.6.3/lib/python3.6/site-packages/tensorflow/python/client/session.py\", line 1259, in _single_operation_run\n",
      "    None)\n",
      "  File \"/home/aat414/pyenv/py3.6.3/lib/python3.6/site-packages/tensorflow/python/framework/errors_impl.py\", line 516, in __exit__\n",
      "    c_api.TF_GetCode(self.status.status))\n",
      "tensorflow.python.framework.errors_impl.CancelledError: Enqueue operation was cancelled\n",
      "\t [[Node: batch/fifo_queue_enqueue = QueueEnqueueV2[Tcomponents=[DT_FLOAT], timeout_ms=-1, _device=\"/job:localhost/replica:0/task:0/device:CPU:0\"](batch/fifo_queue, truediv_2)]]\n",
      "\n",
      "Exception in thread QueueRunnerThread-batch/fifo_queue-batch/fifo_queue_enqueue:\n",
      "Traceback (most recent call last):\n",
      "  File \"/share/apps/python3/3.6.3/intel/lib/python3.6/threading.py\", line 916, in _bootstrap_inner\n",
      "    self.run()\n",
      "  File \"/share/apps/python3/3.6.3/intel/lib/python3.6/threading.py\", line 864, in run\n",
      "    self._target(*self._args, **self._kwargs)\n",
      "  File \"/home/aat414/pyenv/py3.6.3/lib/python3.6/site-packages/tensorflow/python/training/queue_runner_impl.py\", line 252, in _run\n",
      "    enqueue_callable()\n",
      "  File \"/home/aat414/pyenv/py3.6.3/lib/python3.6/site-packages/tensorflow/python/client/session.py\", line 1259, in _single_operation_run\n",
      "    None)\n",
      "  File \"/home/aat414/pyenv/py3.6.3/lib/python3.6/site-packages/tensorflow/python/framework/errors_impl.py\", line 516, in __exit__\n",
      "    c_api.TF_GetCode(self.status.status))\n",
      "tensorflow.python.framework.errors_impl.CancelledError: Enqueue operation was cancelled\n",
      "\t [[Node: batch/fifo_queue_enqueue = QueueEnqueueV2[Tcomponents=[DT_FLOAT], timeout_ms=-1, _device=\"/job:localhost/replica:0/task:0/device:CPU:0\"](batch/fifo_queue, truediv_2)]]\n",
      "\n",
      "Exception in thread QueueRunnerThread-batch/fifo_queue-batch/fifo_queue_enqueue:\n",
      "Traceback (most recent call last):\n",
      "  File \"/share/apps/python3/3.6.3/intel/lib/python3.6/threading.py\", line 916, in _bootstrap_inner\n",
      "    self.run()\n",
      "  File \"/share/apps/python3/3.6.3/intel/lib/python3.6/threading.py\", line 864, in run\n",
      "    self._target(*self._args, **self._kwargs)\n",
      "  File \"/home/aat414/pyenv/py3.6.3/lib/python3.6/site-packages/tensorflow/python/training/queue_runner_impl.py\", line 252, in _run\n",
      "    enqueue_callable()\n",
      "  File \"/home/aat414/pyenv/py3.6.3/lib/python3.6/site-packages/tensorflow/python/client/session.py\", line 1259, in _single_operation_run\n",
      "    None)\n",
      "  File \"/home/aat414/pyenv/py3.6.3/lib/python3.6/site-packages/tensorflow/python/framework/errors_impl.py\", line 516, in __exit__\n",
      "    c_api.TF_GetCode(self.status.status))\n",
      "tensorflow.python.framework.errors_impl.CancelledError: Enqueue operation was cancelled\n",
      "\t [[Node: batch/fifo_queue_enqueue = QueueEnqueueV2[Tcomponents=[DT_FLOAT], timeout_ms=-1, _device=\"/job:localhost/replica:0/task:0/device:CPU:0\"](batch/fifo_queue, truediv_2)]]\n",
      "\n",
      "Exception in thread QueueRunnerThread-input_producer/input_producer-input_producer/input_producer/input_producer_EnqueueMany:\n",
      "Traceback (most recent call last):\n",
      "  File \"/share/apps/python3/3.6.3/intel/lib/python3.6/threading.py\", line 916, in _bootstrap_inner\n",
      "    self.run()\n",
      "  File \"/share/apps/python3/3.6.3/intel/lib/python3.6/threading.py\", line 864, in run\n",
      "    self._target(*self._args, **self._kwargs)\n",
      "  File \"/home/aat414/pyenv/py3.6.3/lib/python3.6/site-packages/tensorflow/python/training/queue_runner_impl.py\", line 252, in _run\n",
      "    enqueue_callable()\n",
      "  File \"/home/aat414/pyenv/py3.6.3/lib/python3.6/site-packages/tensorflow/python/client/session.py\", line 1259, in _single_operation_run\n",
      "    None)\n",
      "  File \"/home/aat414/pyenv/py3.6.3/lib/python3.6/site-packages/tensorflow/python/framework/errors_impl.py\", line 516, in __exit__\n",
      "    c_api.TF_GetCode(self.status.status))\n",
      "tensorflow.python.framework.errors_impl.CancelledError: Enqueue operation was cancelled\n",
      "\t [[Node: input_producer/input_producer/input_producer_EnqueueMany = QueueEnqueueManyV2[Tcomponents=[DT_INT32], timeout_ms=-1, _device=\"/job:localhost/replica:0/task:0/device:CPU:0\"](input_producer/input_producer, input_producer/input_producer/RandomShuffle)]]\n",
      "\n",
      "Exception in thread QueueRunnerThread-batch/fifo_queue-batch/fifo_queue_enqueue:\n",
      "Traceback (most recent call last):\n",
      "  File \"/share/apps/python3/3.6.3/intel/lib/python3.6/threading.py\", line 916, in _bootstrap_inner\n",
      "    self.run()\n",
      "  File \"/share/apps/python3/3.6.3/intel/lib/python3.6/threading.py\", line 864, in run\n",
      "    self._target(*self._args, **self._kwargs)\n",
      "  File \"/home/aat414/pyenv/py3.6.3/lib/python3.6/site-packages/tensorflow/python/training/queue_runner_impl.py\", line 252, in _run\n",
      "    enqueue_callable()\n",
      "  File \"/home/aat414/pyenv/py3.6.3/lib/python3.6/site-packages/tensorflow/python/client/session.py\", line 1259, in _single_operation_run\n",
      "    None)\n",
      "  File \"/home/aat414/pyenv/py3.6.3/lib/python3.6/site-packages/tensorflow/python/framework/errors_impl.py\", line 516, in __exit__\n",
      "    c_api.TF_GetCode(self.status.status))\n",
      "tensorflow.python.framework.errors_impl.CancelledError: Enqueue operation was cancelled\n",
      "\t [[Node: batch/fifo_queue_enqueue = QueueEnqueueV2[Tcomponents=[DT_FLOAT], timeout_ms=-1, _device=\"/job:localhost/replica:0/task:0/device:CPU:0\"](batch/fifo_queue, truediv_2)]]\n",
      "\n",
      "Exception in thread QueueRunnerThread-batch/fifo_queue-batch/fifo_queue_enqueue:\n",
      "Traceback (most recent call last):\n",
      "  File \"/share/apps/python3/3.6.3/intel/lib/python3.6/threading.py\", line 916, in _bootstrap_inner\n",
      "    self.run()\n",
      "  File \"/share/apps/python3/3.6.3/intel/lib/python3.6/threading.py\", line 864, in run\n",
      "    self._target(*self._args, **self._kwargs)\n",
      "  File \"/home/aat414/pyenv/py3.6.3/lib/python3.6/site-packages/tensorflow/python/training/queue_runner_impl.py\", line 252, in _run\n",
      "    enqueue_callable()\n",
      "  File \"/home/aat414/pyenv/py3.6.3/lib/python3.6/site-packages/tensorflow/python/client/session.py\", line 1259, in _single_operation_run\n",
      "    None)\n",
      "  File \"/home/aat414/pyenv/py3.6.3/lib/python3.6/site-packages/tensorflow/python/framework/errors_impl.py\", line 516, in __exit__\n",
      "    c_api.TF_GetCode(self.status.status))\n",
      "tensorflow.python.framework.errors_impl.CancelledError: Enqueue operation was cancelled\n",
      "\t [[Node: batch/fifo_queue_enqueue = QueueEnqueueV2[Tcomponents=[DT_FLOAT], timeout_ms=-1, _device=\"/job:localhost/replica:0/task:0/device:CPU:0\"](batch/fifo_queue, truediv_2)]]\n",
      "\n",
      "Exception in thread QueueRunnerThread-batch/fifo_queue-batch/fifo_queue_enqueue:\n",
      "Traceback (most recent call last):\n",
      "  File \"/share/apps/python3/3.6.3/intel/lib/python3.6/threading.py\", line 916, in _bootstrap_inner\n",
      "    self.run()\n",
      "  File \"/share/apps/python3/3.6.3/intel/lib/python3.6/threading.py\", line 864, in run\n",
      "    self._target(*self._args, **self._kwargs)\n",
      "  File \"/home/aat414/pyenv/py3.6.3/lib/python3.6/site-packages/tensorflow/python/training/queue_runner_impl.py\", line 252, in _run\n",
      "    enqueue_callable()\n",
      "  File \"/home/aat414/pyenv/py3.6.3/lib/python3.6/site-packages/tensorflow/python/client/session.py\", line 1259, in _single_operation_run\n",
      "    None)\n",
      "  File \"/home/aat414/pyenv/py3.6.3/lib/python3.6/site-packages/tensorflow/python/framework/errors_impl.py\", line 516, in __exit__\n",
      "    c_api.TF_GetCode(self.status.status))\n",
      "tensorflow.python.framework.errors_impl.CancelledError: Enqueue operation was cancelled\n",
      "\t [[Node: batch/fifo_queue_enqueue = QueueEnqueueV2[Tcomponents=[DT_FLOAT], timeout_ms=-1, _device=\"/job:localhost/replica:0/task:0/device:CPU:0\"](batch/fifo_queue, truediv_2)]]\n",
      "\n",
      "Exception in thread QueueRunnerThread-batch/fifo_queue-batch/fifo_queue_enqueue:\n",
      "Traceback (most recent call last):\n",
      "  File \"/share/apps/python3/3.6.3/intel/lib/python3.6/threading.py\", line 916, in _bootstrap_inner\n",
      "    self.run()\n",
      "  File \"/share/apps/python3/3.6.3/intel/lib/python3.6/threading.py\", line 864, in run\n",
      "    self._target(*self._args, **self._kwargs)\n",
      "  File \"/home/aat414/pyenv/py3.6.3/lib/python3.6/site-packages/tensorflow/python/training/queue_runner_impl.py\", line 252, in _run\n",
      "    enqueue_callable()\n",
      "  File \"/home/aat414/pyenv/py3.6.3/lib/python3.6/site-packages/tensorflow/python/client/session.py\", line 1259, in _single_operation_run\n",
      "    None)\n",
      "  File \"/home/aat414/pyenv/py3.6.3/lib/python3.6/site-packages/tensorflow/python/framework/errors_impl.py\", line 516, in __exit__\n",
      "    c_api.TF_GetCode(self.status.status))\n",
      "tensorflow.python.framework.errors_impl.CancelledError: Enqueue operation was cancelled\n",
      "\t [[Node: batch/fifo_queue_enqueue = QueueEnqueueV2[Tcomponents=[DT_FLOAT], timeout_ms=-1, _device=\"/job:localhost/replica:0/task:0/device:CPU:0\"](batch/fifo_queue, truediv_2)]]\n",
      "\n",
      "Exception in thread QueueRunnerThread-batch/fifo_queue-batch/fifo_queue_enqueue:\n",
      "Traceback (most recent call last):\n",
      "  File \"/share/apps/python3/3.6.3/intel/lib/python3.6/threading.py\", line 916, in _bootstrap_inner\n",
      "    self.run()\n",
      "  File \"/share/apps/python3/3.6.3/intel/lib/python3.6/threading.py\", line 864, in run\n",
      "    self._target(*self._args, **self._kwargs)\n",
      "  File \"/home/aat414/pyenv/py3.6.3/lib/python3.6/site-packages/tensorflow/python/training/queue_runner_impl.py\", line 252, in _run\n",
      "    enqueue_callable()\n",
      "  File \"/home/aat414/pyenv/py3.6.3/lib/python3.6/site-packages/tensorflow/python/client/session.py\", line 1259, in _single_operation_run\n",
      "    None)\n",
      "  File \"/home/aat414/pyenv/py3.6.3/lib/python3.6/site-packages/tensorflow/python/framework/errors_impl.py\", line 516, in __exit__\n",
      "    c_api.TF_GetCode(self.status.status))\n",
      "tensorflow.python.framework.errors_impl.CancelledError: Enqueue operation was cancelled\n",
      "\t [[Node: batch/fifo_queue_enqueue = QueueEnqueueV2[Tcomponents=[DT_FLOAT], timeout_ms=-1, _device=\"/job:localhost/replica:0/task:0/device:CPU:0\"](batch/fifo_queue, truediv_2)]]\n",
      "\n",
      "Exception in thread QueueRunnerThread-batch/fifo_queue-batch/fifo_queue_enqueue:\n",
      "Traceback (most recent call last):\n",
      "  File \"/share/apps/python3/3.6.3/intel/lib/python3.6/threading.py\", line 916, in _bootstrap_inner\n",
      "    self.run()\n",
      "  File \"/share/apps/python3/3.6.3/intel/lib/python3.6/threading.py\", line 864, in run\n",
      "    self._target(*self._args, **self._kwargs)\n",
      "  File \"/home/aat414/pyenv/py3.6.3/lib/python3.6/site-packages/tensorflow/python/training/queue_runner_impl.py\", line 252, in _run\n",
      "    enqueue_callable()\n",
      "  File \"/home/aat414/pyenv/py3.6.3/lib/python3.6/site-packages/tensorflow/python/client/session.py\", line 1259, in _single_operation_run\n",
      "    None)\n",
      "  File \"/home/aat414/pyenv/py3.6.3/lib/python3.6/site-packages/tensorflow/python/framework/errors_impl.py\", line 516, in __exit__\n",
      "    c_api.TF_GetCode(self.status.status))\n",
      "tensorflow.python.framework.errors_impl.CancelledError: Enqueue operation was cancelled\n",
      "\t [[Node: batch/fifo_queue_enqueue = QueueEnqueueV2[Tcomponents=[DT_FLOAT], timeout_ms=-1, _device=\"/job:localhost/replica:0/task:0/device:CPU:0\"](batch/fifo_queue, truediv_2)]]\n",
      "\n",
      "Exception in thread QueueRunnerThread-batch/fifo_queue-batch/fifo_queue_enqueue:\n",
      "Traceback (most recent call last):\n",
      "  File \"/share/apps/python3/3.6.3/intel/lib/python3.6/threading.py\", line 916, in _bootstrap_inner\n",
      "    self.run()\n",
      "  File \"/share/apps/python3/3.6.3/intel/lib/python3.6/threading.py\", line 864, in run\n",
      "    self._target(*self._args, **self._kwargs)\n",
      "  File \"/home/aat414/pyenv/py3.6.3/lib/python3.6/site-packages/tensorflow/python/training/queue_runner_impl.py\", line 252, in _run\n",
      "    enqueue_callable()\n",
      "  File \"/home/aat414/pyenv/py3.6.3/lib/python3.6/site-packages/tensorflow/python/client/session.py\", line 1259, in _single_operation_run\n",
      "    None)\n",
      "  File \"/home/aat414/pyenv/py3.6.3/lib/python3.6/site-packages/tensorflow/python/framework/errors_impl.py\", line 516, in __exit__\n",
      "    c_api.TF_GetCode(self.status.status))\n",
      "tensorflow.python.framework.errors_impl.CancelledError: Enqueue operation was cancelled\n",
      "\t [[Node: batch/fifo_queue_enqueue = QueueEnqueueV2[Tcomponents=[DT_FLOAT], timeout_ms=-1, _device=\"/job:localhost/replica:0/task:0/device:CPU:0\"](batch/fifo_queue, truediv_2)]]\n",
      "\n",
      "Exception in thread QueueRunnerThread-batch/fifo_queue-batch/fifo_queue_enqueue:\n",
      "Traceback (most recent call last):\n",
      "  File \"/share/apps/python3/3.6.3/intel/lib/python3.6/threading.py\", line 916, in _bootstrap_inner\n",
      "    self.run()\n",
      "  File \"/share/apps/python3/3.6.3/intel/lib/python3.6/threading.py\", line 864, in run\n",
      "    self._target(*self._args, **self._kwargs)\n",
      "  File \"/home/aat414/pyenv/py3.6.3/lib/python3.6/site-packages/tensorflow/python/training/queue_runner_impl.py\", line 252, in _run\n",
      "    enqueue_callable()\n",
      "  File \"/home/aat414/pyenv/py3.6.3/lib/python3.6/site-packages/tensorflow/python/client/session.py\", line 1259, in _single_operation_run\n",
      "    None)\n",
      "  File \"/home/aat414/pyenv/py3.6.3/lib/python3.6/site-packages/tensorflow/python/framework/errors_impl.py\", line 516, in __exit__\n",
      "    c_api.TF_GetCode(self.status.status))\n",
      "tensorflow.python.framework.errors_impl.CancelledError: Enqueue operation was cancelled\n",
      "\t [[Node: batch/fifo_queue_enqueue = QueueEnqueueV2[Tcomponents=[DT_FLOAT], timeout_ms=-1, _device=\"/job:localhost/replica:0/task:0/device:CPU:0\"](batch/fifo_queue, truediv_2)]]\n",
      "\n",
      "Exception in thread QueueRunnerThread-batch/fifo_queue-batch/fifo_queue_enqueue:\n",
      "Traceback (most recent call last):\n",
      "  File \"/share/apps/python3/3.6.3/intel/lib/python3.6/threading.py\", line 916, in _bootstrap_inner\n",
      "    self.run()\n",
      "  File \"/share/apps/python3/3.6.3/intel/lib/python3.6/threading.py\", line 864, in run\n",
      "    self._target(*self._args, **self._kwargs)\n",
      "  File \"/home/aat414/pyenv/py3.6.3/lib/python3.6/site-packages/tensorflow/python/training/queue_runner_impl.py\", line 252, in _run\n",
      "    enqueue_callable()\n",
      "  File \"/home/aat414/pyenv/py3.6.3/lib/python3.6/site-packages/tensorflow/python/client/session.py\", line 1259, in _single_operation_run\n",
      "    None)\n",
      "  File \"/home/aat414/pyenv/py3.6.3/lib/python3.6/site-packages/tensorflow/python/framework/errors_impl.py\", line 516, in __exit__\n",
      "    c_api.TF_GetCode(self.status.status))\n",
      "tensorflow.python.framework.errors_impl.CancelledError: Enqueue operation was cancelled\n",
      "\t [[Node: batch/fifo_queue_enqueue = QueueEnqueueV2[Tcomponents=[DT_FLOAT], timeout_ms=-1, _device=\"/job:localhost/replica:0/task:0/device:CPU:0\"](batch/fifo_queue, truediv_2)]]\n",
      "\n"
     ]
    },
    {
     "ename": "NotFoundError",
     "evalue": "Unsuccessful TensorSliceReader constructor: Failed to find any matching files for D:\\Data\\pgan\\models/8x8/model-1000\n\t [[Node: save_1/RestoreV2 = RestoreV2[dtypes=[DT_FLOAT, DT_FLOAT, DT_FLOAT, DT_FLOAT, DT_FLOAT, ..., DT_FLOAT, DT_FLOAT, DT_FLOAT, DT_FLOAT, DT_INT32], _device=\"/job:localhost/replica:0/task:0/device:CPU:0\"](_arg_save_1/Const_0_0, save_1/RestoreV2/tensor_names, save_1/RestoreV2/shape_and_slices)]]\n\nCaused by op 'save_1/RestoreV2', defined at:\n  File \"/share/apps/python3/3.6.3/intel/lib/python3.6/runpy.py\", line 193, in _run_module_as_main\n    \"__main__\", mod_spec)\n  File \"/share/apps/python3/3.6.3/intel/lib/python3.6/runpy.py\", line 85, in _run_code\n    exec(code, run_globals)\n  File \"/home/aat414/pyenv/py3.6.3/lib/python3.6/site-packages/ipykernel_launcher.py\", line 16, in <module>\n    app.launch_new_instance()\n  File \"/share/apps/python3/3.6.3/intel/lib/python3.6/site-packages/traitlets-4.3.2-py3.6.egg/traitlets/config/application.py\", line 658, in launch_instance\n    app.start()\n  File \"/home/aat414/pyenv/py3.6.3/lib/python3.6/site-packages/ipykernel/kernelapp.py\", line 486, in start\n    self.io_loop.start()\n  File \"/home/aat414/pyenv/py3.6.3/lib/python3.6/site-packages/tornado/platform/asyncio.py\", line 112, in start\n    self.asyncio_loop.run_forever()\n  File \"/share/apps/python3/3.6.3/intel/lib/python3.6/asyncio/base_events.py\", line 421, in run_forever\n    self._run_once()\n  File \"/share/apps/python3/3.6.3/intel/lib/python3.6/asyncio/base_events.py\", line 1426, in _run_once\n    handle._run()\n  File \"/share/apps/python3/3.6.3/intel/lib/python3.6/asyncio/events.py\", line 127, in _run\n    self._callback(*self._args)\n  File \"/home/aat414/pyenv/py3.6.3/lib/python3.6/site-packages/tornado/platform/asyncio.py\", line 102, in _handle_events\n    handler_func(fileobj, events)\n  File \"/home/aat414/pyenv/py3.6.3/lib/python3.6/site-packages/tornado/stack_context.py\", line 276, in null_wrapper\n    return fn(*args, **kwargs)\n  File \"/home/aat414/pyenv/py3.6.3/lib/python3.6/site-packages/zmq/eventloop/zmqstream.py\", line 450, in _handle_events\n    self._handle_recv()\n  File \"/home/aat414/pyenv/py3.6.3/lib/python3.6/site-packages/zmq/eventloop/zmqstream.py\", line 480, in _handle_recv\n    self._run_callback(callback, msg)\n  File \"/home/aat414/pyenv/py3.6.3/lib/python3.6/site-packages/zmq/eventloop/zmqstream.py\", line 432, in _run_callback\n    callback(*args, **kwargs)\n  File \"/home/aat414/pyenv/py3.6.3/lib/python3.6/site-packages/tornado/stack_context.py\", line 276, in null_wrapper\n    return fn(*args, **kwargs)\n  File \"/home/aat414/pyenv/py3.6.3/lib/python3.6/site-packages/ipykernel/kernelbase.py\", line 283, in dispatcher\n    return self.dispatch_shell(stream, msg)\n  File \"/home/aat414/pyenv/py3.6.3/lib/python3.6/site-packages/ipykernel/kernelbase.py\", line 233, in dispatch_shell\n    handler(stream, idents, msg)\n  File \"/home/aat414/pyenv/py3.6.3/lib/python3.6/site-packages/ipykernel/kernelbase.py\", line 399, in execute_request\n    user_expressions, allow_stdin)\n  File \"/home/aat414/pyenv/py3.6.3/lib/python3.6/site-packages/ipykernel/ipkernel.py\", line 208, in do_execute\n    res = shell.run_cell(code, store_history=store_history, silent=silent)\n  File \"/home/aat414/pyenv/py3.6.3/lib/python3.6/site-packages/ipykernel/zmqshell.py\", line 537, in run_cell\n    return super(ZMQInteractiveShell, self).run_cell(*args, **kwargs)\n  File \"/share/apps/python3/3.6.3/intel/lib/python3.6/site-packages/ipython-6.2.1-py3.6.egg/IPython/core/interactiveshell.py\", line 2728, in run_cell\n    interactivity=interactivity, compiler=compiler, result=result)\n  File \"/share/apps/python3/3.6.3/intel/lib/python3.6/site-packages/ipython-6.2.1-py3.6.egg/IPython/core/interactiveshell.py\", line 2856, in run_ast_nodes\n    if self.run_code(code, result):\n  File \"/share/apps/python3/3.6.3/intel/lib/python3.6/site-packages/ipython-6.2.1-py3.6.egg/IPython/core/interactiveshell.py\", line 2910, in run_code\n    exec(code_obj, self.user_global_ns, self.user_ns)\n  File \"<ipython-input-4-a1dfd0d7c5f3>\", line 6, in <module>\n    model.train()\n  File \"/home/aat414/deep_final_project/progressive_growing_of_GANs/model.py\", line 217, in train\n    gen_images = self.generate_images(save_tag, alpha=alpha)\n  File \"/home/aat414/deep_final_project/progressive_growing_of_GANs/model.py\", line 232, in generate_images\n    saver = tf.train.Saver()\n  File \"/home/aat414/pyenv/py3.6.3/lib/python3.6/site-packages/tensorflow/python/training/saver.py\", line 1293, in __init__\n    self.build()\n  File \"/home/aat414/pyenv/py3.6.3/lib/python3.6/site-packages/tensorflow/python/training/saver.py\", line 1302, in build\n    self._build(self._filename, build_save=True, build_restore=True)\n  File \"/home/aat414/pyenv/py3.6.3/lib/python3.6/site-packages/tensorflow/python/training/saver.py\", line 1339, in _build\n    build_save=build_save, build_restore=build_restore)\n  File \"/home/aat414/pyenv/py3.6.3/lib/python3.6/site-packages/tensorflow/python/training/saver.py\", line 796, in _build_internal\n    restore_sequentially, reshape)\n  File \"/home/aat414/pyenv/py3.6.3/lib/python3.6/site-packages/tensorflow/python/training/saver.py\", line 449, in _AddRestoreOps\n    restore_sequentially)\n  File \"/home/aat414/pyenv/py3.6.3/lib/python3.6/site-packages/tensorflow/python/training/saver.py\", line 847, in bulk_restore\n    return io_ops.restore_v2(filename_tensor, names, slices, dtypes)\n  File \"/home/aat414/pyenv/py3.6.3/lib/python3.6/site-packages/tensorflow/python/ops/gen_io_ops.py\", line 1030, in restore_v2\n    shape_and_slices=shape_and_slices, dtypes=dtypes, name=name)\n  File \"/home/aat414/pyenv/py3.6.3/lib/python3.6/site-packages/tensorflow/python/framework/op_def_library.py\", line 787, in _apply_op_helper\n    op_def=op_def)\n  File \"/home/aat414/pyenv/py3.6.3/lib/python3.6/site-packages/tensorflow/python/framework/ops.py\", line 3271, in create_op\n    op_def=op_def)\n  File \"/home/aat414/pyenv/py3.6.3/lib/python3.6/site-packages/tensorflow/python/framework/ops.py\", line 1650, in __init__\n    self._traceback = self._graph._extract_stack()  # pylint: disable=protected-access\n\nNotFoundError (see above for traceback): Unsuccessful TensorSliceReader constructor: Failed to find any matching files for D:\\Data\\pgan\\models/8x8/model-1000\n\t [[Node: save_1/RestoreV2 = RestoreV2[dtypes=[DT_FLOAT, DT_FLOAT, DT_FLOAT, DT_FLOAT, DT_FLOAT, ..., DT_FLOAT, DT_FLOAT, DT_FLOAT, DT_FLOAT, DT_INT32], _device=\"/job:localhost/replica:0/task:0/device:CPU:0\"](_arg_save_1/Const_0_0, save_1/RestoreV2/tensor_names, save_1/RestoreV2/shape_and_slices)]]\n",
     "output_type": "error",
     "traceback": [
      "\u001b[0;31m---------------------------------------------------------------------------\u001b[0m",
      "\u001b[0;31mNotFoundError\u001b[0m                             Traceback (most recent call last)",
      "\u001b[0;32m~/pyenv/py3.6.3/lib/python3.6/site-packages/tensorflow/python/client/session.py\u001b[0m in \u001b[0;36m_do_call\u001b[0;34m(self, fn, *args)\u001b[0m\n\u001b[1;32m   1360\u001b[0m     \u001b[0;32mtry\u001b[0m\u001b[0;34m:\u001b[0m\u001b[0;34m\u001b[0m\u001b[0m\n\u001b[0;32m-> 1361\u001b[0;31m       \u001b[0;32mreturn\u001b[0m \u001b[0mfn\u001b[0m\u001b[0;34m(\u001b[0m\u001b[0;34m*\u001b[0m\u001b[0margs\u001b[0m\u001b[0;34m)\u001b[0m\u001b[0;34m\u001b[0m\u001b[0m\n\u001b[0m\u001b[1;32m   1362\u001b[0m     \u001b[0;32mexcept\u001b[0m \u001b[0merrors\u001b[0m\u001b[0;34m.\u001b[0m\u001b[0mOpError\u001b[0m \u001b[0;32mas\u001b[0m \u001b[0me\u001b[0m\u001b[0;34m:\u001b[0m\u001b[0;34m\u001b[0m\u001b[0m\n",
      "\u001b[0;32m~/pyenv/py3.6.3/lib/python3.6/site-packages/tensorflow/python/client/session.py\u001b[0m in \u001b[0;36m_run_fn\u001b[0;34m(session, feed_dict, fetch_list, target_list, options, run_metadata)\u001b[0m\n\u001b[1;32m   1339\u001b[0m           return tf_session.TF_Run(session, options, feed_dict, fetch_list,\n\u001b[0;32m-> 1340\u001b[0;31m                                    target_list, status, run_metadata)\n\u001b[0m\u001b[1;32m   1341\u001b[0m \u001b[0;34m\u001b[0m\u001b[0m\n",
      "\u001b[0;32m~/pyenv/py3.6.3/lib/python3.6/site-packages/tensorflow/python/framework/errors_impl.py\u001b[0m in \u001b[0;36m__exit__\u001b[0;34m(self, type_arg, value_arg, traceback_arg)\u001b[0m\n\u001b[1;32m    515\u001b[0m             \u001b[0mcompat\u001b[0m\u001b[0;34m.\u001b[0m\u001b[0mas_text\u001b[0m\u001b[0;34m(\u001b[0m\u001b[0mc_api\u001b[0m\u001b[0;34m.\u001b[0m\u001b[0mTF_Message\u001b[0m\u001b[0;34m(\u001b[0m\u001b[0mself\u001b[0m\u001b[0;34m.\u001b[0m\u001b[0mstatus\u001b[0m\u001b[0;34m.\u001b[0m\u001b[0mstatus\u001b[0m\u001b[0;34m)\u001b[0m\u001b[0;34m)\u001b[0m\u001b[0;34m,\u001b[0m\u001b[0;34m\u001b[0m\u001b[0m\n\u001b[0;32m--> 516\u001b[0;31m             c_api.TF_GetCode(self.status.status))\n\u001b[0m\u001b[1;32m    517\u001b[0m     \u001b[0;31m# Delete the underlying status object from memory otherwise it stays alive\u001b[0m\u001b[0;34m\u001b[0m\u001b[0;34m\u001b[0m\u001b[0m\n",
      "\u001b[0;31mNotFoundError\u001b[0m: Unsuccessful TensorSliceReader constructor: Failed to find any matching files for D:\\Data\\pgan\\models/8x8/model-1000\n\t [[Node: save_1/RestoreV2 = RestoreV2[dtypes=[DT_FLOAT, DT_FLOAT, DT_FLOAT, DT_FLOAT, DT_FLOAT, ..., DT_FLOAT, DT_FLOAT, DT_FLOAT, DT_FLOAT, DT_INT32], _device=\"/job:localhost/replica:0/task:0/device:CPU:0\"](_arg_save_1/Const_0_0, save_1/RestoreV2/tensor_names, save_1/RestoreV2/shape_and_slices)]]",
      "\nDuring handling of the above exception, another exception occurred:\n",
      "\u001b[0;31mNotFoundError\u001b[0m                             Traceback (most recent call last)",
      "\u001b[0;32m<ipython-input-4-a1dfd0d7c5f3>\u001b[0m in \u001b[0;36m<module>\u001b[0;34m()\u001b[0m\n\u001b[1;32m      4\u001b[0m \u001b[0;34m\u001b[0m\u001b[0m\n\u001b[1;32m      5\u001b[0m \u001b[0mmodel\u001b[0m \u001b[0;34m=\u001b[0m \u001b[0mDCGAN\u001b[0m\u001b[0;34m(\u001b[0m\u001b[0mcfg\u001b[0m\u001b[0;34m)\u001b[0m\u001b[0;34m\u001b[0m\u001b[0m\n\u001b[0;32m----> 6\u001b[0;31m \u001b[0mmodel\u001b[0m\u001b[0;34m.\u001b[0m\u001b[0mtrain\u001b[0m\u001b[0;34m(\u001b[0m\u001b[0;34m)\u001b[0m\u001b[0;34m\u001b[0m\u001b[0m\n\u001b[0m",
      "\u001b[0;32m~/deep_final_project/progressive_growing_of_GANs/model.py\u001b[0m in \u001b[0;36mtrain\u001b[0;34m(self)\u001b[0m\n\u001b[1;32m    215\u001b[0m                     \u001b[0msaver\u001b[0m\u001b[0;34m.\u001b[0m\u001b[0msave\u001b[0m\u001b[0;34m(\u001b[0m\u001b[0msess\u001b[0m\u001b[0;34m,\u001b[0m \u001b[0msave_dir\u001b[0m\u001b[0;34m,\u001b[0m \u001b[0mglobal_step\u001b[0m\u001b[0;34m)\u001b[0m\u001b[0;34m\u001b[0m\u001b[0m\n\u001b[1;32m    216\u001b[0m                     \u001b[0;32mif\u001b[0m \u001b[0mself\u001b[0m\u001b[0;34m.\u001b[0m\u001b[0mcfg\u001b[0m\u001b[0;34m.\u001b[0m\u001b[0msave_images\u001b[0m\u001b[0;34m:\u001b[0m\u001b[0;34m\u001b[0m\u001b[0m\n\u001b[0;32m--> 217\u001b[0;31m                         \u001b[0mgen_images\u001b[0m \u001b[0;34m=\u001b[0m \u001b[0mself\u001b[0m\u001b[0;34m.\u001b[0m\u001b[0mgenerate_images\u001b[0m\u001b[0;34m(\u001b[0m\u001b[0msave_tag\u001b[0m\u001b[0;34m,\u001b[0m \u001b[0malpha\u001b[0m\u001b[0;34m=\u001b[0m\u001b[0malpha\u001b[0m\u001b[0;34m)\u001b[0m\u001b[0;34m\u001b[0m\u001b[0m\n\u001b[0m\u001b[1;32m    218\u001b[0m                         \u001b[0mplt\u001b[0m\u001b[0;34m.\u001b[0m\u001b[0mfigure\u001b[0m\u001b[0;34m(\u001b[0m\u001b[0mfigsize\u001b[0m\u001b[0;34m=\u001b[0m\u001b[0;34m(\u001b[0m\u001b[0;36m10\u001b[0m\u001b[0;34m,\u001b[0m \u001b[0;36m10\u001b[0m\u001b[0;34m)\u001b[0m\u001b[0;34m)\u001b[0m\u001b[0;34m\u001b[0m\u001b[0m\n\u001b[1;32m    219\u001b[0m                         \u001b[0mgrid\u001b[0m \u001b[0;34m=\u001b[0m \u001b[0mimage_loader\u001b[0m\u001b[0;34m.\u001b[0m\u001b[0mgrid_batch_images\u001b[0m\u001b[0;34m(\u001b[0m\u001b[0mgen_images\u001b[0m\u001b[0;34m)\u001b[0m\u001b[0;34m\u001b[0m\u001b[0m\n",
      "\u001b[0;32m~/deep_final_project/progressive_growing_of_GANs/model.py\u001b[0m in \u001b[0;36mgenerate_images\u001b[0;34m(self, model, batch_z, alpha)\u001b[0m\n\u001b[1;32m    237\u001b[0m \u001b[0;34m\u001b[0m\u001b[0m\n\u001b[1;32m    238\u001b[0m         \u001b[0;32mwith\u001b[0m \u001b[0mtf\u001b[0m\u001b[0;34m.\u001b[0m\u001b[0mSession\u001b[0m\u001b[0;34m(\u001b[0m\u001b[0;34m)\u001b[0m \u001b[0;32mas\u001b[0m \u001b[0msess\u001b[0m\u001b[0;34m:\u001b[0m\u001b[0;34m\u001b[0m\u001b[0m\n\u001b[0;32m--> 239\u001b[0;31m             \u001b[0mself\u001b[0m\u001b[0;34m.\u001b[0m\u001b[0mload\u001b[0m\u001b[0;34m(\u001b[0m\u001b[0msess\u001b[0m\u001b[0;34m,\u001b[0m \u001b[0msaver\u001b[0m\u001b[0;34m,\u001b[0m \u001b[0mmodel\u001b[0m\u001b[0;34m)\u001b[0m\u001b[0;34m\u001b[0m\u001b[0m\n\u001b[0m\u001b[1;32m    240\u001b[0m             \u001b[0mgen_images\u001b[0m \u001b[0;34m=\u001b[0m \u001b[0msess\u001b[0m\u001b[0;34m.\u001b[0m\u001b[0mrun\u001b[0m\u001b[0;34m(\u001b[0m\u001b[0mgen\u001b[0m\u001b[0;34m,\u001b[0m \u001b[0mfeed_dict\u001b[0m\u001b[0;34m=\u001b[0m\u001b[0mfeed_dict\u001b[0m\u001b[0;34m)\u001b[0m\u001b[0;34m\u001b[0m\u001b[0m\n\u001b[1;32m    241\u001b[0m             \u001b[0mgen_images\u001b[0m \u001b[0;34m=\u001b[0m \u001b[0mimage_loader\u001b[0m\u001b[0;34m.\u001b[0m\u001b[0mpostprocess_image\u001b[0m\u001b[0;34m(\u001b[0m\u001b[0mgen_images\u001b[0m\u001b[0;34m)\u001b[0m\u001b[0;34m\u001b[0m\u001b[0m\n",
      "\u001b[0;32m~/deep_final_project/progressive_growing_of_GANs/model.py\u001b[0m in \u001b[0;36mload\u001b[0;34m(self, sess, saver, tag)\u001b[0m\n\u001b[1;32m    253\u001b[0m             \u001b[0mprint\u001b[0m\u001b[0;34m(\u001b[0m\u001b[0;34m\"Error: No saved model found. Please train first.\"\u001b[0m\u001b[0;34m)\u001b[0m\u001b[0;34m\u001b[0m\u001b[0m\n\u001b[1;32m    254\u001b[0m             \u001b[0msys\u001b[0m\u001b[0;34m.\u001b[0m\u001b[0mexit\u001b[0m\u001b[0;34m(\u001b[0m\u001b[0;36m0\u001b[0m\u001b[0;34m)\u001b[0m\u001b[0;34m\u001b[0m\u001b[0m\n\u001b[0;32m--> 255\u001b[0;31m         \u001b[0msaver\u001b[0m\u001b[0;34m.\u001b[0m\u001b[0mrestore\u001b[0m\u001b[0;34m(\u001b[0m\u001b[0msess\u001b[0m\u001b[0;34m,\u001b[0m \u001b[0mcheckpoint\u001b[0m\u001b[0;34m.\u001b[0m\u001b[0mmodel_checkpoint_path\u001b[0m\u001b[0;34m)\u001b[0m\u001b[0;34m\u001b[0m\u001b[0m\n\u001b[0m",
      "\u001b[0;32m~/pyenv/py3.6.3/lib/python3.6/site-packages/tensorflow/python/training/saver.py\u001b[0m in \u001b[0;36mrestore\u001b[0;34m(self, sess, save_path)\u001b[0m\n\u001b[1;32m   1753\u001b[0m     \u001b[0;32mif\u001b[0m \u001b[0mcontext\u001b[0m\u001b[0;34m.\u001b[0m\u001b[0min_graph_mode\u001b[0m\u001b[0;34m(\u001b[0m\u001b[0;34m)\u001b[0m\u001b[0;34m:\u001b[0m\u001b[0;34m\u001b[0m\u001b[0m\n\u001b[1;32m   1754\u001b[0m       sess.run(self.saver_def.restore_op_name,\n\u001b[0;32m-> 1755\u001b[0;31m                {self.saver_def.filename_tensor_name: save_path})\n\u001b[0m\u001b[1;32m   1756\u001b[0m     \u001b[0;32melse\u001b[0m\u001b[0;34m:\u001b[0m\u001b[0;34m\u001b[0m\u001b[0m\n\u001b[1;32m   1757\u001b[0m       \u001b[0mself\u001b[0m\u001b[0;34m.\u001b[0m\u001b[0m_build_eager\u001b[0m\u001b[0;34m(\u001b[0m\u001b[0msave_path\u001b[0m\u001b[0;34m,\u001b[0m \u001b[0mbuild_save\u001b[0m\u001b[0;34m=\u001b[0m\u001b[0;32mFalse\u001b[0m\u001b[0;34m,\u001b[0m \u001b[0mbuild_restore\u001b[0m\u001b[0;34m=\u001b[0m\u001b[0;32mTrue\u001b[0m\u001b[0;34m)\u001b[0m\u001b[0;34m\u001b[0m\u001b[0m\n",
      "\u001b[0;32m~/pyenv/py3.6.3/lib/python3.6/site-packages/tensorflow/python/client/session.py\u001b[0m in \u001b[0;36mrun\u001b[0;34m(self, fetches, feed_dict, options, run_metadata)\u001b[0m\n\u001b[1;32m    903\u001b[0m     \u001b[0;32mtry\u001b[0m\u001b[0;34m:\u001b[0m\u001b[0;34m\u001b[0m\u001b[0m\n\u001b[1;32m    904\u001b[0m       result = self._run(None, fetches, feed_dict, options_ptr,\n\u001b[0;32m--> 905\u001b[0;31m                          run_metadata_ptr)\n\u001b[0m\u001b[1;32m    906\u001b[0m       \u001b[0;32mif\u001b[0m \u001b[0mrun_metadata\u001b[0m\u001b[0;34m:\u001b[0m\u001b[0;34m\u001b[0m\u001b[0m\n\u001b[1;32m    907\u001b[0m         \u001b[0mproto_data\u001b[0m \u001b[0;34m=\u001b[0m \u001b[0mtf_session\u001b[0m\u001b[0;34m.\u001b[0m\u001b[0mTF_GetBuffer\u001b[0m\u001b[0;34m(\u001b[0m\u001b[0mrun_metadata_ptr\u001b[0m\u001b[0;34m)\u001b[0m\u001b[0;34m\u001b[0m\u001b[0m\n",
      "\u001b[0;32m~/pyenv/py3.6.3/lib/python3.6/site-packages/tensorflow/python/client/session.py\u001b[0m in \u001b[0;36m_run\u001b[0;34m(self, handle, fetches, feed_dict, options, run_metadata)\u001b[0m\n\u001b[1;32m   1135\u001b[0m     \u001b[0;32mif\u001b[0m \u001b[0mfinal_fetches\u001b[0m \u001b[0;32mor\u001b[0m \u001b[0mfinal_targets\u001b[0m \u001b[0;32mor\u001b[0m \u001b[0;34m(\u001b[0m\u001b[0mhandle\u001b[0m \u001b[0;32mand\u001b[0m \u001b[0mfeed_dict_tensor\u001b[0m\u001b[0;34m)\u001b[0m\u001b[0;34m:\u001b[0m\u001b[0;34m\u001b[0m\u001b[0m\n\u001b[1;32m   1136\u001b[0m       results = self._do_run(handle, final_targets, final_fetches,\n\u001b[0;32m-> 1137\u001b[0;31m                              feed_dict_tensor, options, run_metadata)\n\u001b[0m\u001b[1;32m   1138\u001b[0m     \u001b[0;32melse\u001b[0m\u001b[0;34m:\u001b[0m\u001b[0;34m\u001b[0m\u001b[0m\n\u001b[1;32m   1139\u001b[0m       \u001b[0mresults\u001b[0m \u001b[0;34m=\u001b[0m \u001b[0;34m[\u001b[0m\u001b[0;34m]\u001b[0m\u001b[0;34m\u001b[0m\u001b[0m\n",
      "\u001b[0;32m~/pyenv/py3.6.3/lib/python3.6/site-packages/tensorflow/python/client/session.py\u001b[0m in \u001b[0;36m_do_run\u001b[0;34m(self, handle, target_list, fetch_list, feed_dict, options, run_metadata)\u001b[0m\n\u001b[1;32m   1353\u001b[0m     \u001b[0;32mif\u001b[0m \u001b[0mhandle\u001b[0m \u001b[0;32mis\u001b[0m \u001b[0;32mNone\u001b[0m\u001b[0;34m:\u001b[0m\u001b[0;34m\u001b[0m\u001b[0m\n\u001b[1;32m   1354\u001b[0m       return self._do_call(_run_fn, self._session, feeds, fetches, targets,\n\u001b[0;32m-> 1355\u001b[0;31m                            options, run_metadata)\n\u001b[0m\u001b[1;32m   1356\u001b[0m     \u001b[0;32melse\u001b[0m\u001b[0;34m:\u001b[0m\u001b[0;34m\u001b[0m\u001b[0m\n\u001b[1;32m   1357\u001b[0m       \u001b[0;32mreturn\u001b[0m \u001b[0mself\u001b[0m\u001b[0;34m.\u001b[0m\u001b[0m_do_call\u001b[0m\u001b[0;34m(\u001b[0m\u001b[0m_prun_fn\u001b[0m\u001b[0;34m,\u001b[0m \u001b[0mself\u001b[0m\u001b[0;34m.\u001b[0m\u001b[0m_session\u001b[0m\u001b[0;34m,\u001b[0m \u001b[0mhandle\u001b[0m\u001b[0;34m,\u001b[0m \u001b[0mfeeds\u001b[0m\u001b[0;34m,\u001b[0m \u001b[0mfetches\u001b[0m\u001b[0;34m)\u001b[0m\u001b[0;34m\u001b[0m\u001b[0m\n",
      "\u001b[0;32m~/pyenv/py3.6.3/lib/python3.6/site-packages/tensorflow/python/client/session.py\u001b[0m in \u001b[0;36m_do_call\u001b[0;34m(self, fn, *args)\u001b[0m\n\u001b[1;32m   1372\u001b[0m         \u001b[0;32mexcept\u001b[0m \u001b[0mKeyError\u001b[0m\u001b[0;34m:\u001b[0m\u001b[0;34m\u001b[0m\u001b[0m\n\u001b[1;32m   1373\u001b[0m           \u001b[0;32mpass\u001b[0m\u001b[0;34m\u001b[0m\u001b[0m\n\u001b[0;32m-> 1374\u001b[0;31m       \u001b[0;32mraise\u001b[0m \u001b[0mtype\u001b[0m\u001b[0;34m(\u001b[0m\u001b[0me\u001b[0m\u001b[0;34m)\u001b[0m\u001b[0;34m(\u001b[0m\u001b[0mnode_def\u001b[0m\u001b[0;34m,\u001b[0m \u001b[0mop\u001b[0m\u001b[0;34m,\u001b[0m \u001b[0mmessage\u001b[0m\u001b[0;34m)\u001b[0m\u001b[0;34m\u001b[0m\u001b[0m\n\u001b[0m\u001b[1;32m   1375\u001b[0m \u001b[0;34m\u001b[0m\u001b[0m\n\u001b[1;32m   1376\u001b[0m   \u001b[0;32mdef\u001b[0m \u001b[0m_extend_graph\u001b[0m\u001b[0;34m(\u001b[0m\u001b[0mself\u001b[0m\u001b[0;34m)\u001b[0m\u001b[0;34m:\u001b[0m\u001b[0;34m\u001b[0m\u001b[0m\n",
      "\u001b[0;31mNotFoundError\u001b[0m: Unsuccessful TensorSliceReader constructor: Failed to find any matching files for D:\\Data\\pgan\\models/8x8/model-1000\n\t [[Node: save_1/RestoreV2 = RestoreV2[dtypes=[DT_FLOAT, DT_FLOAT, DT_FLOAT, DT_FLOAT, DT_FLOAT, ..., DT_FLOAT, DT_FLOAT, DT_FLOAT, DT_FLOAT, DT_INT32], _device=\"/job:localhost/replica:0/task:0/device:CPU:0\"](_arg_save_1/Const_0_0, save_1/RestoreV2/tensor_names, save_1/RestoreV2/shape_and_slices)]]\n\nCaused by op 'save_1/RestoreV2', defined at:\n  File \"/share/apps/python3/3.6.3/intel/lib/python3.6/runpy.py\", line 193, in _run_module_as_main\n    \"__main__\", mod_spec)\n  File \"/share/apps/python3/3.6.3/intel/lib/python3.6/runpy.py\", line 85, in _run_code\n    exec(code, run_globals)\n  File \"/home/aat414/pyenv/py3.6.3/lib/python3.6/site-packages/ipykernel_launcher.py\", line 16, in <module>\n    app.launch_new_instance()\n  File \"/share/apps/python3/3.6.3/intel/lib/python3.6/site-packages/traitlets-4.3.2-py3.6.egg/traitlets/config/application.py\", line 658, in launch_instance\n    app.start()\n  File \"/home/aat414/pyenv/py3.6.3/lib/python3.6/site-packages/ipykernel/kernelapp.py\", line 486, in start\n    self.io_loop.start()\n  File \"/home/aat414/pyenv/py3.6.3/lib/python3.6/site-packages/tornado/platform/asyncio.py\", line 112, in start\n    self.asyncio_loop.run_forever()\n  File \"/share/apps/python3/3.6.3/intel/lib/python3.6/asyncio/base_events.py\", line 421, in run_forever\n    self._run_once()\n  File \"/share/apps/python3/3.6.3/intel/lib/python3.6/asyncio/base_events.py\", line 1426, in _run_once\n    handle._run()\n  File \"/share/apps/python3/3.6.3/intel/lib/python3.6/asyncio/events.py\", line 127, in _run\n    self._callback(*self._args)\n  File \"/home/aat414/pyenv/py3.6.3/lib/python3.6/site-packages/tornado/platform/asyncio.py\", line 102, in _handle_events\n    handler_func(fileobj, events)\n  File \"/home/aat414/pyenv/py3.6.3/lib/python3.6/site-packages/tornado/stack_context.py\", line 276, in null_wrapper\n    return fn(*args, **kwargs)\n  File \"/home/aat414/pyenv/py3.6.3/lib/python3.6/site-packages/zmq/eventloop/zmqstream.py\", line 450, in _handle_events\n    self._handle_recv()\n  File \"/home/aat414/pyenv/py3.6.3/lib/python3.6/site-packages/zmq/eventloop/zmqstream.py\", line 480, in _handle_recv\n    self._run_callback(callback, msg)\n  File \"/home/aat414/pyenv/py3.6.3/lib/python3.6/site-packages/zmq/eventloop/zmqstream.py\", line 432, in _run_callback\n    callback(*args, **kwargs)\n  File \"/home/aat414/pyenv/py3.6.3/lib/python3.6/site-packages/tornado/stack_context.py\", line 276, in null_wrapper\n    return fn(*args, **kwargs)\n  File \"/home/aat414/pyenv/py3.6.3/lib/python3.6/site-packages/ipykernel/kernelbase.py\", line 283, in dispatcher\n    return self.dispatch_shell(stream, msg)\n  File \"/home/aat414/pyenv/py3.6.3/lib/python3.6/site-packages/ipykernel/kernelbase.py\", line 233, in dispatch_shell\n    handler(stream, idents, msg)\n  File \"/home/aat414/pyenv/py3.6.3/lib/python3.6/site-packages/ipykernel/kernelbase.py\", line 399, in execute_request\n    user_expressions, allow_stdin)\n  File \"/home/aat414/pyenv/py3.6.3/lib/python3.6/site-packages/ipykernel/ipkernel.py\", line 208, in do_execute\n    res = shell.run_cell(code, store_history=store_history, silent=silent)\n  File \"/home/aat414/pyenv/py3.6.3/lib/python3.6/site-packages/ipykernel/zmqshell.py\", line 537, in run_cell\n    return super(ZMQInteractiveShell, self).run_cell(*args, **kwargs)\n  File \"/share/apps/python3/3.6.3/intel/lib/python3.6/site-packages/ipython-6.2.1-py3.6.egg/IPython/core/interactiveshell.py\", line 2728, in run_cell\n    interactivity=interactivity, compiler=compiler, result=result)\n  File \"/share/apps/python3/3.6.3/intel/lib/python3.6/site-packages/ipython-6.2.1-py3.6.egg/IPython/core/interactiveshell.py\", line 2856, in run_ast_nodes\n    if self.run_code(code, result):\n  File \"/share/apps/python3/3.6.3/intel/lib/python3.6/site-packages/ipython-6.2.1-py3.6.egg/IPython/core/interactiveshell.py\", line 2910, in run_code\n    exec(code_obj, self.user_global_ns, self.user_ns)\n  File \"<ipython-input-4-a1dfd0d7c5f3>\", line 6, in <module>\n    model.train()\n  File \"/home/aat414/deep_final_project/progressive_growing_of_GANs/model.py\", line 217, in train\n    gen_images = self.generate_images(save_tag, alpha=alpha)\n  File \"/home/aat414/deep_final_project/progressive_growing_of_GANs/model.py\", line 232, in generate_images\n    saver = tf.train.Saver()\n  File \"/home/aat414/pyenv/py3.6.3/lib/python3.6/site-packages/tensorflow/python/training/saver.py\", line 1293, in __init__\n    self.build()\n  File \"/home/aat414/pyenv/py3.6.3/lib/python3.6/site-packages/tensorflow/python/training/saver.py\", line 1302, in build\n    self._build(self._filename, build_save=True, build_restore=True)\n  File \"/home/aat414/pyenv/py3.6.3/lib/python3.6/site-packages/tensorflow/python/training/saver.py\", line 1339, in _build\n    build_save=build_save, build_restore=build_restore)\n  File \"/home/aat414/pyenv/py3.6.3/lib/python3.6/site-packages/tensorflow/python/training/saver.py\", line 796, in _build_internal\n    restore_sequentially, reshape)\n  File \"/home/aat414/pyenv/py3.6.3/lib/python3.6/site-packages/tensorflow/python/training/saver.py\", line 449, in _AddRestoreOps\n    restore_sequentially)\n  File \"/home/aat414/pyenv/py3.6.3/lib/python3.6/site-packages/tensorflow/python/training/saver.py\", line 847, in bulk_restore\n    return io_ops.restore_v2(filename_tensor, names, slices, dtypes)\n  File \"/home/aat414/pyenv/py3.6.3/lib/python3.6/site-packages/tensorflow/python/ops/gen_io_ops.py\", line 1030, in restore_v2\n    shape_and_slices=shape_and_slices, dtypes=dtypes, name=name)\n  File \"/home/aat414/pyenv/py3.6.3/lib/python3.6/site-packages/tensorflow/python/framework/op_def_library.py\", line 787, in _apply_op_helper\n    op_def=op_def)\n  File \"/home/aat414/pyenv/py3.6.3/lib/python3.6/site-packages/tensorflow/python/framework/ops.py\", line 3271, in create_op\n    op_def=op_def)\n  File \"/home/aat414/pyenv/py3.6.3/lib/python3.6/site-packages/tensorflow/python/framework/ops.py\", line 1650, in __init__\n    self._traceback = self._graph._extract_stack()  # pylint: disable=protected-access\n\nNotFoundError (see above for traceback): Unsuccessful TensorSliceReader constructor: Failed to find any matching files for D:\\Data\\pgan\\models/8x8/model-1000\n\t [[Node: save_1/RestoreV2 = RestoreV2[dtypes=[DT_FLOAT, DT_FLOAT, DT_FLOAT, DT_FLOAT, DT_FLOAT, ..., DT_FLOAT, DT_FLOAT, DT_FLOAT, DT_FLOAT, DT_INT32], _device=\"/job:localhost/replica:0/task:0/device:CPU:0\"](_arg_save_1/Const_0_0, save_1/RestoreV2/tensor_names, save_1/RestoreV2/shape_and_slices)]]\n"
     ]
    }
   ],
   "source": [
    "cfg.resolution = 8\n",
    "cfg.transition = False\n",
    "cfg.load_model = None\n",
    "\n",
    "model = DCGAN(cfg)\n",
    "model.train()"
   ]
  },
  {
   "cell_type": "markdown",
   "metadata": {},
   "source": [
    "### Step-2 : Transition from 8x8 to 16x16 resolution (fading)\n",
    "Note that this step will automatically load model from 8x8 resolution (`models/8x8`). So, you can leave `cfg.load_model = None`."
   ]
  },
  {
   "cell_type": "code",
   "execution_count": null,
   "metadata": {},
   "outputs": [],
   "source": [
    "cfg.resolution = 16\n",
    "cfg.transition = True\n",
    "cfg.load_model = None\n",
    "\n",
    "model = DCGAN(cfg)\n",
    "model.train()"
   ]
  },
  {
   "cell_type": "markdown",
   "metadata": {},
   "source": [
    "### Step-3 : Train at  16x16 resolution\n",
    "Now, you must load model from previous step to continue. Model from previous step is saved in `models/16x16_transition`, so we set `cfg.load_model = '16x16_transition`."
   ]
  },
  {
   "cell_type": "code",
   "execution_count": null,
   "metadata": {},
   "outputs": [],
   "source": [
    "cfg.resolution = 16\n",
    "cfg.transition = False\n",
    "cfg.load_model = '16x16_transition'\n",
    "\n",
    "model = DCGAN(cfg)\n",
    "model.train()"
   ]
  },
  {
   "cell_type": "markdown",
   "metadata": {},
   "source": [
    "### Step-4 : Transition from 16x16 to 32x32 resolution (fading)\n",
    "Again, this step will automatically load model from `models/16x16`."
   ]
  },
  {
   "cell_type": "code",
   "execution_count": null,
   "metadata": {},
   "outputs": [],
   "source": [
    "cfg.resolution = 32\n",
    "cfg.transition = True\n",
    "cfg.load_model = None\n",
    "\n",
    "model = DCGAN(cfg)\n",
    "model.train()"
   ]
  },
  {
   "cell_type": "markdown",
   "metadata": {},
   "source": [
    "### Step-5 : Train at  32x32 resolution\n",
    "Now, we load model from previous step saved in `models/32x32_transition`"
   ]
  },
  {
   "cell_type": "code",
   "execution_count": null,
   "metadata": {},
   "outputs": [],
   "source": [
    "cfg.resolution = 32\n",
    "cfg.transition = False\n",
    "cfg.load_model = '32x32_transition'\n",
    "\n",
    "model = DCGAN(cfg)\n",
    "model.train()"
   ]
  },
  {
   "cell_type": "markdown",
   "metadata": {},
   "source": [
    "Hopefully, you get the idea now. So you can continue this process to higher resolutions. "
   ]
  },
  {
   "cell_type": "code",
   "execution_count": null,
   "metadata": {},
   "outputs": [],
   "source": []
  }
 ],
 "metadata": {
  "kernelspec": {
   "display_name": "Python 3",
   "language": "python",
   "name": "python3"
  },
  "language_info": {
   "codemirror_mode": {
    "name": "ipython",
    "version": 3
   },
   "file_extension": ".py",
   "mimetype": "text/x-python",
   "name": "python",
   "nbconvert_exporter": "python",
   "pygments_lexer": "ipython3",
   "version": "3.6.3"
  }
 },
 "nbformat": 4,
 "nbformat_minor": 2
}
